Workbook

Sheet Plan. Vendas
C3: Planejamento de Vendas Por Trimestre | L3: Gap
C4: Canal | D4: Trimentre | E4: % de Faturamento | F4: Faturamento | G4: Média Mês | H4: Faturamento 2026 | L4: R$ | M4: %
C5: Fardin | D5: 1º | E5: 0.16 | F5: =8700000*E5 -> 1392000 | G5: 608000 | H5: 1464217.9 | L5: =H5-F5 -> 72217.88 | M5: =H5/F5 -> 1.0518807
D6: 2º | E6: 0.24 | F6: =8700000*E6 -> 2088000 | G6: 912000 | H6: 1790098.7 | L6: =H6-F6 -> -297901.27 | M6: =H6/F6 -> 0.85732698
D7: 3º | E7: 0.36 | F7: =8700000*E7 -> 3132000 | G7: 1368000
D8: 4º | E8: 0.24 | F8: =8700000*E8 -> 2088000 | G8: 912000
C9: Privaty e Terceiros | D9: 1º | E9: 0.2 | F9: =16580000*E9 -> 3316000 | G9: 973333.33 | H9: 2685570.6 | L9: -630429.44 | M9: 0.8099
D10: 2º | E10: 0.25 | F10: =16580000*E10 -> 4145000 | G10: 1216666.7
D11: 3º | E11: 0.28 | F11: =16580000*E11 -> 4642400 | G11: 1362666.7
D12: 4º | E12: 0.27 | F12: =16580000*E12 -> 4476600 | G12: 1314000
C14: Meta por Família
C15: Copinho | D15: Mariola Zero | E15: Mariola | F15: Mariola Cristalizada | G15: Goiabada | H15: Gominha
C16: 500000 | D16: 3200000 | E16: 3500000 | F16: 1250000 | G16: 50000 | H16: 200000 | L16: Gap
C17: Fardin | D17: Trimestre | E17: Família | F17: % Tri. | G17: Total Desejado R$ | H17: Total Alcançado R$ | L17: R$ | M17: %
D18: 1º | E18: Copinho | F18: 0.16 | G18: =C16*F18 -> 80000 | H18: =SUM('Histórico de Fatu. FARDIN P.F.'!E12:G12) -> 51406.66 | L18: =H18-G18 -> -28593.34 | M18: =IF(G18="","",H18/G18)-100% -> -0.35741675
E19: Mariola Zero | F19: 0.16 | G19: =D16*F19 -> 512000 | H19: =SUM('Histórico de Fatu. FARDIN P.F.'!E16:G16) -> 525420.68 | L19: =H19-G19 -> 13420.68 | M19: =IF(G19="","",H19/G19)-100% -> 0.026212266
E20: Mariola | F20: 0.16 | G20: =E16*F20 -> 560000 | H20: =SUM('Histórico de Fatu. FARDIN P.F.'!E20:G20) -> 517349.56 | L20: =H20-G20 -> -42650.44 | M20: =IF(G20="","",H20/G20)-100% -> -0.0761615
E21: Mariola Cristalizada | F21: 0.16 | G21: =F16*F21 -> 200000 | H21: =SUM('Histórico de Fatu. FARDIN P.F.'!E24:G24) -> 268468.36 | L21: =H21-G21 -> 68468.36 | M21: =IF(G21="","",H21/G21)-100% -> 0.3423418
E22: Goiabada | F22: 0.16 | G22: =G16*F22 -> 8000 | H22: =SUM('Histórico de Fatu. FARDIN P.F.'!E32:G32) -> 23062.84 | L22: =H22-G22 -> 15062.84 | M22: =IF(G22="","",H22/G22)-100% -> 1.882855
E23: Gominha | F23: 0.16 | G23: =H16*F23 -> 32000 | H23: =SUM('Histórico de Fatu. FARDIN P.F.'!E28:G28) -> 66735.69 | L23: =H23-G23 -> 34735.69 | M23: =IF(G23="","",H23/G23)-100% -> 1.0854903
D24: 2º | E24: Copinho | F24: 0.24 | G24: =C16*F24 -> 120000 | H24: =SUM('Histórico de Fatu. FARDIN P.F.'!H12:J12) -> 71526.46 | L24: =H24-G24 -> -48473.54 | M24: =IF(G24="","",H24/G24)-100% -> -0.40394617
E25: Mariola Zero | F25: 0.24 | G25: =D16*F25 -> 768000 | H25: =SUM('Histórico de Fatu. FARDIN P.F.'!H16:J16) -> 700390.97 | L25: =H25-G25 -> -67609.03 | M25: =IF(G25="","",H25/G25)-100% -> -0.088032591
E26: Mariola | F26: 0.24 | G26: =E16*F26 -> 840000 | H26: =SUM('Histórico de Fatu. FARDIN P.F.'!H20:J20) -> 561006.93 | L26: =H26-G26 -> -278993.07 | M26: =IF(G26="","",H26/G26)-100% -> -0.33213461
E27: Mariola Cristalizada | F27: 0.24 | G27: =F16*F27 -> 300000 | H27: =SUM('Histórico de Fatu. FARDIN P.F.'!H24:J24) -> 347381.25 | L27: =H27-G27 -> 47381.25 | M27: =IF(G27="","",H27/G27)-100% -> 0.1579375
E28: Goiabada | F28: 0.24 | G28: =G16*F28 -> 12000 | H28: =SUM('Histórico de Fatu. FARDIN P.F.'!H32:J32) -> 16464.57 | L28: =H28-G28 -> 4464.57 | M28: =IF(G28="","",H28/G28)-100% -> 0.3720475
E29: Gominha | F29: 0.24 | G29: =H16*F29 -> 48000 | H29: =SUM('Histórico de Fatu. FARDIN P.F.'!H28:J28) -> 77859.47 | L29: =H29-G29 -> 29859.47 | M29: =IF(G29="","",H29/G29)-100% -> 0.62207229
D30: 3º | E30: Copinho | F30: 0.36 | G30: =C16*F30 -> 180000 | H30: 0
E31: Mariola Zero | F31: 0.36 | G31: =D16*F31 -> 1152000 | H31: 0
E32: Mariola | F32: 0.36 | G32: =E16*F32 -> 1260000 | H32: 0
E33: Mariola Cristalizada | F33: 0.36 | G33: =F16*F33 -> 450000 | H33: 0
E34: Goiabada | F34: 0.36 | G34: =G16*F34 -> 18000 | H34: 0
E35: Gominha | F35: 0.36 | G35: =H16*F35 -> 72000 | H35: 0
D36: 4º | E36: Copinho | F36: 0.24 | G36: =C16*F36 -> 120000 | H36: 0
E37: Mariola Zero | F37: 0.24 | G37: =D16*F37 -> 768000 | H37: 0
E38: Mariola | F38: 0.24 | G38: =E16*F38 -> 840000 | H38: 0
E39: Mariola Cristalizada | F39: 0.24 | G39: =F16*F39 -> 300000 | H39: 0
E40: Goiabada | F40: 0.24 | G40: =G16*F40 -> 12000 | H40: 0
E41: Gominha | F41: 0.24 | G41: =H16*F41 -> 48000 | H41: 0

Sheet Evolução de Vendas Mês GLOBAL
B2: Avaliação de Desempenho da Evolução de Vendas GLOBAL 2026
B3: Período Base | D3: Realizado
B4: Meses | C4: R$ Vendas | D4: Meses | E4: R$ Vendas | F4: Evolução de Vendas | G4: Ganho (R$)
G5: Acumulado | H5: Média Mensal | I5: Anualizado | K5: % de Crescimento 25x26 | L5: Média de Crescimento
B6: 45658 | C6: 1120797.9 | D6: 46023 | E6: =IF('Meta x Real de Vendas Global'!D7=0,"",'Meta x Real de Vendas Global'!D7) -> 1152212 | F6: =IF(E6="","",(E6-C6)) -> 31414.05 | G6: =IF(F6="","",F6) -> 31414.05 | H6: =IF(F6="","",AVERAGE(F6)) -> 31414.05 | I6: =IF(H6="","",(H6*12)) -> 376968.6 | K6: =E6/C6-100% -> 0.02802829 | L6: =AVERAGE(K6:K17) -> 0.02881146
B7: 45690 | C7: 1402392.4 | D7: 46055 | E7: =IF('Meta x Real de Vendas Global'!D8=0,"",'Meta x Real de Vendas Global'!D8) -> 1234828.6 | F7: =IF(E7="","",(E7-C7)) -> -167563.84 | G7: =IF(F7="","",F7+G6) -> -136149.79 | H7: =IF(F7="","",AVERAGE(F6:F7)) -> -68074.895 | I7: =IF(H7="","",(H7*12)) -> -816898.74 | K7: =E7/C7-100% -> -0.11948427
B8: 45721 | C8: 1565806.9 | D8: 46086 | E8: =IF('Meta x Real de Vendas Global'!D9=0,"",'Meta x Real de Vendas Global'!D9) -> 1766523.9 | F8: =IF(E8="","",(E8-C8)) -> 200716.95 | G8: =IF(F8="","",F8+G7) -> 64567.16 | H8: =IF(F8="","",AVERAGE(F6:F8)) -> 21522.387 | I8: =IF(H8="","",(H8*12)) -> 258268.64 | K8: =E8/C8-100% -> 0.12818755
B9: 45752 | C9: 1485920.6 | D9: 46117 | E9: 1870979.6 | F9: =IF(E9="","",(E9-C9)) -> 385058.95 | G9: =IF(F9="","",F9+G8) -> 449626.11 | H9: =IF(F9="","",AVERAGE(F6:F9)) -> 112406.53 | I9: =IF(H9="","",(H9*12)) -> 1348878.3 | K9: =E9/C9-100% -> 0.2591383
B10: 45783 | C10: 1946329 | D10: 46148 | E10: =IF('Meta x Real de Vendas Global'!D11=0,"",'Meta x Real de Vendas Global'!D11) -> 1650851.8 | F10: =IF(E10="","",(E10-C10)) -> -295477.2 | G10: =IF(F10="","",F10+G9) -> 154148.91 | H10: =IF(F10="","",AVERAGE(F6:F10)) -> 30829.782 | I10: =IF(H10="","",(H10*12)) -> 369957.38 | K10: =E10/C10-100% -> -0.15181257
B11: 45814 | C11: 1589981.4 | D11: 46179 | E11: =IF('Meta x Real de Vendas Global'!D12=0,"",'Meta x Real de Vendas Global'!D12) | F11: =IF(E11="","",(E11-C11)) | G11: =IF(F11="","",F11+G10) | H11: =IF(F11="","",AVERAGE(F6:F11)) | I11: =IF(H11="","",(H11*12))
B12: 45845 | C12: 2106751.1 | D12: 46210 | E12: =IF('Meta x Real de Vendas Global'!D13=0,"",'Meta x Real de Vendas Global'!D13) | F12: =IF(E12="","",(E12-C12)) | G12: =IF(F12="","",F12+G11) | H12: =IF(F12="","",AVERAGE(F6:F12)) | I12: =IF(H12="","",(H12*12))
B13: 45876 | C13: 1874283.5 | D13: 46241 | E13: =IF('Meta x Real de Vendas Global'!D14=0,"",'Meta x Real de Vendas Global'!D14) | F13: =IF(E13="","",(E13-C13)) | G13: =IF(F13="","",F13+G12) | H13: =IF(F13="","",AVERAGE(F6:F13)) | I13: =IF(H13="","",(H13*12))
B14: 45907 | C14: 1834870.1 | D14: 46272 | E14: =IF('Meta x Real de Vendas Global'!D15=0,"",'Meta x Real de Vendas Global'!D15) | F14: =IF(E14="","",(E14-C14)) | G14: =IF(F14="","",F14+G13) | H14: =IF(F14="","",AVERAGE(F6:F14)) | I14: =IF(H14="","",(H14*12))
B15: 45938 | C15: 1807004 | D15: 46303 | E15: =IF('Meta x Real de Vendas Global'!D16=0,"",'Meta x Real de Vendas Global'!D16) | F15: =IF(E15="","",(E15-C15)) | G15: =IF(F15="","",F15+G14) | H15: =IF(F15="","",AVERAGE(F6:F15)) | I15: =IF(H15="","",(H15*12))
B16: 45969 | C16: 1761119.9 | D16: 46334 | E16: =IF('Meta x Real de Vendas Global'!D17=0,"",'Meta x Real de Vendas Global'!D17) | F16: =IF(E16="","",(E16-C16)) | G16: =IF(F16="","",F16+G15) | H16: =IF(F16="","",AVERAGE(F6:F16)) | I16: =IF(H16="","",(H16*12))
B17: 46009 | C17: 1460752 | D17: 46374 | F17: =IF(E17="","",(E17-C17)) | G17: =IF(F17="","",F17+G16) | H17: =IF(F17="","",AVERAGE(F6:F17)) | I17: =IF(H17="","",(H17*12))
B18: Wilson s/ NF 2025 | C18: 600161 | D18: xx
C20: =SUM(C6:C17) -> 19956009 | E20: =SUM(E6:E17) -> 7675395.9 | F20: =E20/C20 -> 0.38461577
D21: Base | E21: Real | F21: Evolução
D22: =IF(C6="","",C6) -> 1120797.9 | E22: =IF(E6="","",E6) -> 1152212 | F22: =IF(E22="","",(E22-D22)) -> 31414.05
D23: =IF(C7="","",C7) -> 1402392.4 | E23: =IF(E7="","",E7) -> 1234828.6 | F23: =IF(E23="","",(E23-D23)) -> -167563.84
D24: =IF(C8="","",C8) -> 1565806.9 | E24: =IF(E8="","",E8) -> 1766523.9 | F24: =IF(E24="","",(E24-D24)) -> 200716.95
D25: =IF(C9="","",C9) -> 1485920.6 | E25: =IF(E9="","",E9) -> 1870979.6 | F25: =IF(E25="","",(E25-D25)) -> 385058.95
D26: =IF(C10="","",C10) -> 1946329 | E26: =IF(E10="","",E10) -> 1650851.8 | F26: =IF(E26="","",(E26-D26)) -> -295477.2
D27: =IF(C11="","",C11) -> 1589981.4 | E27: =IF(E11="","",E11) | F27: =IF(E27="","",(E27-D27))
D28: =IF(C12="","",C12) -> 2106751.1 | E28: =IF(E12="","",E12) | F28: =IF(E28="","",(E28-D28))
D29: =IF(C13="","",C13) -> 1874283.5 | E29: =IF(E13="","",E13) | F29: =IF(E29="","",(E29-D29))
D30: =IF(C14="","",C14) -> 1834870.1 | E30: =IF(E14="","",E14) | F30: =IF(E30="","",(E30-D30))
D31: =IF(C15="","",C15) -> 1807004 | E31: =IF(E15="","",E15) | F31: =IF(E31="","",(E31-D31))
D32: =IF(C16="","",C16) -> 1761119.9 | E32: =IF(E16="","",E16) | F32: =IF(E32="","",(E32-D32))
D33: =IF(C17="","",C17) -> 1460752 | E33: =IF(E17="","",E17) | F33: =IF(E33="","",(E33-D33))

Sheet Meta x Real de Vendas  Global
B2: Meta X Real de Vendas
B3: 2026 | I3: Desafio: | J3: =J4*1.1 -> 28600000
I4: Meta: | J4: 26000000
B5: Data | C5: Meta | D5: Total | E5: Por Categoria de Vendas | H5: % de Atingimento | I5: Venda Acumulada | J5: Falta da Meta
E6: Fardin | F6: Privaty Label | G6: Terceiros
B7: Janeiro | C7: 1290486.8 | D7: =SUM(E7:G7) -> 1152212 | E7: =SUM('Meta x Real de Vendas FARDIN'!R7) -> 399844.11 | F7: 678591.7 | G7: 73776.19 | H7: =IF(D7=0,"",D7/C7) -> 0.89285069 | I7: =D7 -> 1152212 | J7: =J4-D7 -> 24847788
B8: Fevereiro | C8: 1614714.6 | D8: =SUM(E8:G8) -> 1234828.6 | E8: =SUM('Meta x Real de Vendas FARDIN'!R8) -> 401528.5 | F8: 719928.63 | G8: 113371.46 | H8: =IF(D8=0,"",D8/C8) -> 0.76473487 | I8: =IF(D8="",I7,D8+I7) -> 2387040.6 | J8: =J7-D8 -> 23612959
B9: Março | C9: 1802870.1 | D9: =SUM(E9:G9) -> 1766523.9 | E9: =SUM('Meta x Real de Vendas FARDIN'!R9) -> 666621.31 | F9: 933505.16 | G9: 166397.42 | H9: =IF(D9=0,"",D9/C9) -> 0.9798398 | I9: =IF(D9="",I8,D9+I8) -> 4153564.5 | J9: =J8-D9 -> 21846436
B10: Abril | C10: 1844027.5 | D10: =SUM(E10:G10) -> 1870979.6 | E10: =SUM('Meta x Real de Vendas FARDIN'!R10) -> 591216.71 | F10: 1184591.8 | G10: 95171.09 | H10: =IF(D10=0,"",D10/C10) -> 1.0146159 | I10: =IF(D10="",I9,D10+I9) -> 6024544.1 | J10: =J9-D10 -> 19975456
B11: Maio | C11: 2100000 | D11: =SUM(E11:G11) -> 1650851.8 | E11: =SUM('Meta x Real de Vendas FARDIN'!R11) -> 395074.44 | F11: 1077607.6 | G11: 178169.72 | H11: =IF(D11=0,"",D11/C11) -> 0.7861199 | I11: =IF(D11="",I10,D11+I10) -> 7675395.9 | J11: =J10-D11 -> 18324604
B12: Junho | C12: =1973166.97945+165394.28+150000 -> 2288561.3 | H12: =IF(D12=0,"",D12/C12) | I12: =IF(D12="",I11,D12+I11) -> 7675395.9 | J12: =J11-D12 -> 18324604
B13: Julho | C13: 2816094.2 | D13: =SUM(E13:G13) -> 0 | H13: =IF(D13=0,"",D13/C13) | I13: =IF(D13="",I12,D13+I12) -> 7675395.9 | J13: =J12-D13 -> 18324604
B14: Agosto | C14: 2505354.7 | D14: =SUM(E14:G14) -> 0 | H14: =IF(D14=0,"",D14/C14) | I14: =IF(D14="",I13,D14+I13) -> 7675395.9 | J14: =J13-D14 -> 18324604
B15: Setembro | C15: 2452670.9 | D15: =SUM(E15:G15) -> 0 | H15: =IF(D15=0,"",D15/C15) | I15: =IF(D15="",I14,D15+I14) -> 7675395.9 | J15: =J14-D15 -> 18324604
B16: Outubro | C16: =2358826.9076276+625.91 -> 2359452.8 | D16: =SUM(E16:G16) -> 0 | H16: =IF(D16=0,"",D16/C16) | I16: =IF(D16="",I15,D16+I15) -> 7675395.9 | J16: =J15-D16 -> 18324604
B17: Novembro | C17: 2298930.6 | D17: =SUM(E17:G17) -> 0 | H17: =IF(D17=0,"",D17/C17) | I17: =IF(D17="",I16,D17+I16) -> 7675395.9 | J17: =J16-D17 -> 18324604
B18: Dezembro | C18: 1906836.4 | D18: ='Evolução de Vendas Mês GLOBAL'!E17 -> 0 | H18: =IF(D18=0,"",D18/C18) | I18: =IF(D18="",I17,D18+I17) -> 7675395.9 | J18: =J17-D18 -> 18324604
B19: Wilson S/ NF | C19: 720000 | H19: =IF(D19=0,"",D19/C19)
B20: Total | C20: =SUM(C7:C19) -> 26000000 | D20: =SUM(D7:D19) -> 7675395.9 | E20: =SUM(E7:E18) -> 2454285.1 | F20: =SUM(F7:F18) -> 4594224.9 | G20: =SUM(G7:G18) -> 626885.88 | H20: =IF(D20=0,"",D20/C20) -> 0.29520753 | I20: Meta vs Real | J20: =D20-C20 -> -18324604
B23: Falta para a Meta | J23: =IF(D20="","",100%-(D20/J4)) -> 0.70479247
B25: Atingimento da Meta | J25: =100%-J23 -> 0.29520753
C27: Meta | D27: Verde | E27: Vermelho
B28: =B7 -> Janeiro | C28: =C7 -> 1290486.8 | D28: =IF(D7>C7,D7,"") | E28: =IF(D7<C7,D7,"") -> 1152212
B29: =B8 -> Fevereiro | C29: =C8 -> 1614714.6 | D29: =IF(D8>C8,D8,"") | E29: =IF(D8<C8,D8,"") -> 1234828.6
B30: =B9 -> Março | C30: =C9 -> 1802870.1 | D30: =IF(D9>C9,D9,"") | E30: =IF(D9<C9,D9,"") -> 1766523.9
B31: =B10 -> Abril | C31: =C10 -> 1844027.5 | D31: =IF(D10>C10,D10,"") -> 1870979.6 | E31: =IF(D10<C10,D10,"")
B32: =B11 -> Maio | C32: =C11 -> 2100000 | D32: =IF(D11>C11,D11,"") | E32: =IF(D11<C11,D11,"") -> 1650851.8
B33: =B12 -> Junho | C33: =C12 -> 2288561.3 | D33: =IF(D12>C12,D12,"") | E33: =IF(D12<C12,D12,"") -> 0
B34: =B13 -> Julho | C34: =C13 -> 2816094.2 | D34: =IF(D13>C13,D13,"") | E34: =IF(D13<C13,D13,"") -> 0
B35: =B14 -> Agosto | C35: =C14 -> 2505354.7 | D35: =IF(D14>C14,D14,"") | E35: =IF(D14<C14,D14,"") -> 0
B36: =B15 -> Setembro | C36: =C15 -> 2452670.9 | D36: =IF(D15>C15,D15,"") | E36: =IF(D15<C15,D15,"") -> 0
B37: =B16 -> Outubro | C37: =C16 -> 2359452.8 | D37: =IF(D16>C16,D16,"") | E37: =IF(D16<C16,D16,"") -> 0
B38: =B17 -> Novembro | C38: =C17 -> 2298930.6 | D38: =IF(D17>C17,D17,"") | E38: =IF(D17<C17,D17,"") -> 0
B39: =B18 -> Dezembro | C39: =C18 -> 1906836.4 | D39: =IF(D18>C18,D18,"") | E39: =IF(D18<C18,D18,"") -> 0

Sheet Evolução de Vendas Mês FARDIN
B2: Avaliação de Desempenho da Evolução de Vendas FARDIN 2026
B3: Período Base | D3: Realizado
B4: Meses | C4: R$ Vendas | D4: Meses | E4: R$ Vendas | F4: Evolução de Vendas | G4: Ganho (R$)
G5: Acumulado | H5: Média Mensal | I5: Anualizado | L5: % de Crescimento 25x26 | M5: Média de Crescimento
B6: 45658 | C6: 398197.21 | D6: 46023 | E6: 399844.11 | F6: =IF(E6="","",(E6-C6)) -> 1646.9 | G6: =IF(F6="","",F6) -> 1646.9 | H6: =IF(F6="","",AVERAGE(F6)) -> 1646.9 | I6: =IF(H6="","",(H6*12)) -> 19762.8 | L6: =E6/C6-100% -> 0.0041358904 | M6: =AVERAGE(L6:L17) -> 0.19631374
B7: 45690 | C7: 312248.89 | D7: 46055 | E7: 401528.5 | F7: =IF(E7="","",(E7-C7)) -> 89279.61 | G7: =IF(F7="","",F7+G6) -> 90926.51 | H7: =IF(F7="","",AVERAGE(F6:F7)) -> 45463.255 | I7: =IF(H7="","",(H7*12)) -> 545559.06 | L7: =E7/C7-100% -> 0.28592451
B8: 45721 | C8: 532104.43 | D8: 46086 | E8: 662845.27 | F8: =IF(E8="","",(E8-C8)) -> 130740.84 | G8: =IF(F8="","",F8+G7) -> 221667.35 | H8: =IF(F8="","",AVERAGE(F6:F8)) -> 73889.117 | I8: =IF(H8="","",(H8*12)) -> 886669.4 | L8: =E8/C8-100% -> 0.24570523
B9: 45752 | C9: 414130.56 | D9: 46117 | E9: 591216.71 | F9: =IF(E9="","",(E9-C9)) -> 177086.15 | G9: =IF(F9="","",F9+G8) -> 398753.5 | H9: =IF(F9="","",AVERAGE(F6:F9)) -> 99688.375 | I9: =IF(H9="","",(H9*12)) -> 1196260.5 | L9: =E9/C9-100% -> 0.42760947
B10: 45783 | C10: 542304.22 | D10: 46148 | E10: =SUM('Meta x Real de Vendas FARDIN'!R11) -> 395074.44 | F10: =IF(E10="","",(E10-C10)) -> -147229.78 | G10: =IF(F10="","",F10+G9) -> 251523.72 | H10: =IF(F10="","",AVERAGE(F6:F10)) -> 50304.744 | I10: =IF(H10="","",(H10*12)) -> 603656.93 | L10: =E10/C10-100% -> -0.27148928
B11: 45814 | C11: 540921.54 | D11: 46179 | E11: =SUM('Meta x Real de Vendas FARDIN'!R12) -> 803807.58 | F11: =IF(E11="","",(E11-C11)) -> 262886.04 | G11: =IF(F11="","",F11+G10) -> 514409.76 | H11: =IF(F11="","",AVERAGE(F6:F11)) -> 85734.96 | I11: =IF(H11="","",(H11*12)) -> 1028819.5 | L11: =E11/C11-100% -> 0.48599662
B12: 45845 | C12: 725817.27 | D12: 46210 | E12: =IF('Meta x Real de Vendas Global'!D13=0,"",'Meta x Real de Vendas Global'!D13) | F12: =IF(E12="","",(E12-C12)) | G12: =IF(F12="","",F12+G11) | H12: =IF(F12="","",AVERAGE(F6:F12)) | I12: =IF(H12="","",(H12*12))
B13: 45876 | C13: 645154.36 | D13: 46241 | E13: =IF('Meta x Real de Vendas Global'!D14=0,"",'Meta x Real de Vendas Global'!D14) | F13: =IF(E13="","",(E13-C13)) | G13: =IF(F13="","",F13+G12) | H13: =IF(F13="","",AVERAGE(F6:F13)) | I13: =IF(H13="","",(H13*12))
B14: 45907 | C14: 785445.66 | D14: 46272 | E14: =IF('Meta x Real de Vendas Global'!D15=0,"",'Meta x Real de Vendas Global'!D15) | F14: =IF(E14="","",(E14-C14)) | G14: =IF(F14="","",F14+G13) | H14: =IF(F14="","",AVERAGE(F6:F14)) | I14: =IF(H14="","",(H14*12))
B15: 45938 | C15: 785549.95 | D15: 46303 | E15: =IF('Meta x Real de Vendas Global'!D16=0,"",'Meta x Real de Vendas Global'!D16) | F15: =IF(E15="","",(E15-C15)) | G15: =IF(F15="","",F15+G14) | H15: =IF(F15="","",AVERAGE(F6:F15)) | I15: =IF(H15="","",(H15*12))
B16: 45969 | C16: 548892.29 | D16: 46334 | E16: =IF('Meta x Real de Vendas Global'!D17=0,"",'Meta x Real de Vendas Global'!D17) | F16: =IF(E16="","",(E16-C16)) | G16: =IF(F16="","",F16+G15) | H16: =IF(F16="","",AVERAGE(F6:F16)) | I16: =IF(H16="","",(H16*12))
B17: 46009 | C17: 498132.02 | D17: 46374 | F17: =IF(E17="","",(E17-C17)) | G17: =IF(F17="","",F17+G16) | H17: =IF(F17="","",AVERAGE(F6:F17)) | I17: =IF(H17="","",(H17*12))
C19: =SUM(C6:C17) -> 6728898.4 | E19: =SUM(E6:E17) -> 3254316.6 | F19: =E19/C19 -> 0.48363289
D20: Base | E20: Real | F20: Evolução
D21: =IF(C6="","",C6) -> 398197.21 | E21: =IF(E6="","",E6) -> 399844.11 | F21: =IF(E21="","",(E21-D21)) -> 1646.9
D22: =IF(C7="","",C7) -> 312248.89 | E22: =IF(E7="","",E7) -> 401528.5 | F22: =IF(E22="","",(E22-D22)) -> 89279.61
D23: =IF(C8="","",C8) -> 532104.43 | E23: =IF(E8="","",E8) -> 662845.27 | F23: =IF(E23="","",(E23-D23)) -> 130740.84
D24: =IF(C9="","",C9) -> 414130.56 | E24: =IF(E9="","",E9) -> 591216.71 | F24: =IF(E24="","",(E24-D24)) -> 177086.15
D25: =IF(C10="","",C10) -> 542304.22 | E25: =IF(E10="","",E10) -> 395074.44 | F25: =IF(E25="","",(E25-D25)) -> -147229.78
D26: =IF(C11="","",C11) -> 540921.54 | E26: =IF(E11="","",E11) -> 803807.58 | F26: =IF(E26="","",(E26-D26)) -> 262886.04
D27: =IF(C12="","",C12) -> 725817.27 | E27: =IF(E12="","",E12) | F27: =IF(E27="","",(E27-D27))
D28: =IF(C13="","",C13) -> 645154.36 | E28: =IF(E13="","",E13) | F28: =IF(E28="","",(E28-D28))
D29: =IF(C14="","",C14) -> 785445.66 | E29: =IF(E14="","",E14) | F29: =IF(E29="","",(E29-D29))
D30: =IF(C15="","",C15) -> 785549.95 | E30: =IF(E15="","",E15) | F30: =IF(E30="","",(E30-D30))
D31: =IF(C16="","",C16) -> 548892.29 | E31: =IF(E16="","",E16) | F31: =IF(E31="","",(E31-D31))
D32: =IF(C17="","",C17) -> 498132.02 | E32: =IF(E17="","",E17) | F32: =IF(E32="","",(E32-D32))

Sheet Meta x Real de Vendas  FARDIN
B2: Meta X Real de Vendas Categoria Fardin
B3: 2026 | T3: Desafio: | U3: 10700000
T4: Meta: | U4: 8700000
B5: Data | C5: AIRTON | D5: SIMONY | E5: ALEXANDRE | F5: CAPELINE | G5: JULIANO | H5: ROBSON | I5: WALLACE | J5: ANA | K5: Representantes | M5: Doces Fardin | O5: Wilson | Q5: TOTAL
K6: Meta | L6: Real | M6: Meta | N6: Real | O6: Meta | P6: Real | Q6: Meta | R6: Real | S6: % de Atingimento | T6: Venda Acumulada | U6: Falta da Meta
B7: Janeiro | K7: =SUM('Histórico de Fatu. FARDIN P.R.'!E31+'Histórico de Fatu. FARDIN P.R.'!E40+'Histórico de Fatu. FARDIN P.R.'!E46+'Histórico de Fatu. FARDIN P.R.'!E52+'Histórico de Fatu. FARDIN P.R.'!E79) -> 75000 | L7: =SUM('Histórico de Fatu. FARDIN P.R.'!E37,'Histórico de Fatu. FARDIN P.R.'!E43,'Histórico de Fatu. FARDIN P.R.'!E49,'Histórico de Fatu. FARDIN P.R.'!E55,'Histórico de Fatu. FARDIN P.R.'!E64,'Histórico de Fatu. FARDIN P.R.'!E70,'Histórico de Fatu. FARDIN P.R.'!E76) -> 42200.02 | M7: =('Histórico de Fatu. FARDIN P.R.'!E16) -> 115000 | N7: =SUM('Histórico de Fatu. FARDIN P.R.'!E19) -> 51609.93 | O7: =('Histórico de Fatu. FARDIN P.R.'!E22) -> 360000 | P7: =SUM('Histórico de Fatu. FARDIN P.R.'!E28) -> 306034.16 | Q7: =SUM(K7,M7,O7) -> 550000 | R7: =SUM(L7,N7,P7) -> 399844.11 | S7: =IF(R7=0,"",R7/Q7) -> 0.72698929 | T7: =R7 -> 399844.11 | U7: =U4-R7 -> 8300155.9
B8: Fevereiro | K8: =SUM('Histórico de Fatu. FARDIN P.R.'!F31,'Histórico de Fatu. FARDIN P.R.'!F40,'Histórico de Fatu. FARDIN P.R.'!F46,'Histórico de Fatu. FARDIN P.R.'!F52,'Histórico de Fatu. FARDIN P.R.'!F79) -> 160000 | L8: =SUM('Histórico de Fatu. FARDIN P.R.'!F37,'Histórico de Fatu. FARDIN P.R.'!F43,'Histórico de Fatu. FARDIN P.R.'!F49,'Histórico de Fatu. FARDIN P.R.'!F55,'Histórico de Fatu. FARDIN P.R.'!F64,'Histórico de Fatu. FARDIN P.R.'!F70,'Histórico de Fatu. FARDIN P.R.'!F76) -> 49153.68 | M8: =SUM('Histórico de Fatu. FARDIN P.R.'!F16) -> 120000 | N8: =SUM('Histórico de Fatu. FARDIN P.R.'!F19) -> 108390.94 | O8: =('Histórico de Fatu. FARDIN P.R.'!F22) -> 320000 | P8: =SUM('Histórico de Fatu. FARDIN P.R.'!F28) -> 243983.88 | Q8: =SUM(K8,M8,O8) -> 600000 | R8: =SUM(L8,N8,P8) -> 401528.5 | S8: =IF(R8=0,"",R8/Q8) -> 0.66921417 | T8: =IF(R8="",T7,R8+T7) -> 801372.61 | U8: =U7-R8 -> 7898627.4
B9: Março | K9: =SUM('Histórico de Fatu. FARDIN P.R.'!G31,'Histórico de Fatu. FARDIN P.R.'!G40,'Histórico de Fatu. FARDIN P.R.'!G46,'Histórico de Fatu. FARDIN P.R.'!G52,'Histórico de Fatu. FARDIN P.R.'!G67,'Histórico de Fatu. FARDIN P.R.'!G79) -> 165000 | L9: =SUM('Histórico de Fatu. FARDIN P.R.'!G76,'Histórico de Fatu. FARDIN P.R.'!G70,'Histórico de Fatu. FARDIN P.R.'!G64,'Histórico de Fatu. FARDIN P.R.'!G55,'Histórico de Fatu. FARDIN P.R.'!G49,'Histórico de Fatu. FARDIN P.R.'!G43,'Histórico de Fatu. FARDIN P.R.'!G37) -> 196977.47 | M9: =SUM('Histórico de Fatu. FARDIN P.R.'!G16) -> 120000 | N9: =SUM('Histórico de Fatu. FARDIN P.R.'!G19) -> 167634.25 | O9: =('Histórico de Fatu. FARDIN P.R.'!G22) -> 400000 | P9: =SUM('Histórico de Fatu. FARDIN P.R.'!G28) -> 302009.59 | Q9: =SUM(K9,M9,O9) -> 685000 | R9: =SUM(L9,N9,P9) -> 666621.31 | S9: =IF(R9=0,"",R9/Q9) -> 0.9731698 | T9: =IF(R9="",T8,R9+T8) -> 1467993.9 | U9: =U8-R9 -> 7232006.1
B10: Abril | K10: 115000 | L10: =SUM('Histórico de Fatu. FARDIN P.R.'!H37,'Histórico de Fatu. FARDIN P.R.'!H43,'Histórico de Fatu. FARDIN P.R.'!H49,'Histórico de Fatu. FARDIN P.R.'!H55,'Histórico de Fatu. FARDIN P.R.'!H64,'Histórico de Fatu. FARDIN P.R.'!H70,'Histórico de Fatu. FARDIN P.R.'!H76) -> 141376.39 | M10: 175000 | N10: =SUM('Histórico de Fatu. FARDIN P.R.'!H19) -> 113846.33 | O10: 360000 | P10: =SUM('Histórico de Fatu. FARDIN P.R.'!H28) -> 335993.99 | Q10: =SUM(K10,M10,O10) -> 650000 | R10: =SUM(L10,N10,P10) -> 591216.71 | S10: =IF(R10=0,"",R10/Q10) -> 0.90956417 | T10: =IF(R10="",T9,R10+T9) -> 2059210.6 | U10: =U9-R10 -> 6640789.4
B11: Maio | K11: 165000 | L11: =SUM('Histórico de Fatu. FARDIN P.R.'!I37,'Histórico de Fatu. FARDIN P.R.'!I43,'Histórico de Fatu. FARDIN P.R.'!I49,'Histórico de Fatu. FARDIN P.R.'!I55,'Histórico de Fatu. FARDIN P.R.'!I64,'Histórico de Fatu. FARDIN P.R.'!I70,'Histórico de Fatu. FARDIN P.R.'!I76) -> 61184.97 | M11: 185000 | N11: ='Histórico de Fatu. FARDIN P.R.'!I19 -> 100565.47 | O11: 450000 | P11: ='Histórico de Fatu. FARDIN P.R.'!I28 -> 233324 | Q11: =SUM(K11,M11,O11) -> 800000 | R11: =SUM(L11,N11,P11) -> 395074.44 | S11: =IF(R11=0,"",R11/Q11) -> 0.49384305 | T11: =IF(R11="",T10,R11+T10) -> 2454285.1 | U11: =U10-R11 -> 6245714.9
B12: Junho | K12: 160000 | L12: =SUM('Histórico de Fatu. FARDIN P.R.'!J37+'Histórico de Fatu. FARDIN P.R.'!J43+'Histórico de Fatu. FARDIN P.R.'!J49+'Histórico de Fatu. FARDIN P.R.'!J55+'Histórico de Fatu. FARDIN P.R.'!J64+'Histórico de Fatu. FARDIN P.R.'!J70+'Histórico de Fatu. FARDIN P.R.'!J76+'Histórico de Fatu. FARDIN P.R.'!J85) -> 308667.79 | M12: 180000 | N12: ='Histórico de Fatu. FARDIN P.R.'!J19 -> 139358.72 | O12: 475000 | P12: ='Histórico de Fatu. FARDIN P.R.'!J28 -> 355781.07 | Q12: =SUM(K12,M12,O12) -> 815000 | R12: =SUM(L12,N12,P12) -> 803807.58 | S12: =IF(R12=0,"",R12/Q12) -> 0.98626697 | T12: =IF(R12="",T11,R12+T11) -> 3258092.6 | U12: =U11-R12 -> 5441907.3
B13: Julho | K13: 230000 | M13: 170000 | O13: 500000 | Q13: =SUM(K13,M13,O13) -> 900000 | R13: =SUM(L13,N13,P13) -> 0 | S13: =IF(R13=0,"",R13/Q13) | T13: =IF(R13="",T12,R13+T12) -> 3258092.6 | U13: =U12-R13 -> 5441907.3
B14: Agosto | K14: 185000 | M14: 160000 | O14: 485000 | Q14: =SUM(K14,M14,O14) -> 830000 | R14: =SUM(L14,N14,P14) -> 0 | S14: =IF(R14=0,"",R14/Q14) | T14: =IF(R14="",T13,R14+T13) -> 3258092.6 | U14: =U13-R14 -> 5441907.3
B15: Setembro | K15: 200000 | M15: 175000 | O15: 535000 | Q15: =SUM(K15,M15,O15) -> 910000 | R15: =SUM(L15,N15,P15) -> 0 | S15: =IF(R15=0,"",R15/Q15) | T15: =IF(R15="",T14,R15+T14) -> 3258092.6 | U15: =U14-R15 -> 5441907.3
B16: Outubro | K16: 175000 | M16: 150000 | O16: 500000 | Q16: =SUM(K16,M16,O16) -> 825000 | R16: =SUM(L16,N16,P16) -> 0 | S16: =IF(R16=0,"",R16/Q16) | T16: =IF(R16="",T15,R16+T15) -> 3258092.6 | U16: =U15-R16 -> 5441907.3
B17: Novembro | C17: 149636.88 | D17: 481459.33 | E17: 36688.65 | F17: 103387.05 | G17: 119559.44 | H17: 86830.88 | I17: 61577.44 | J17: 45972.21 | K17: 150000 | M17: 115000 | O17: 335000 | Q17: =SUM(K17,M17,O17) -> 600000 | R17: =SUM(L17,N17,P17) -> 0 | S17: =IF(R17=0,"",R17/Q17) | T17: =IF(R17="",T16,R17+T16) -> 3258092.6 | U17: =U16-R17 -> 5441907.3
B18: Dezembro | D18: =67998.5+12375.77 -> 80374.27 | F18: 54077.77 | G18: =24802.96+21511.09 -> 46314.05 | I18: 3691.63 | J18: 8280 | K18: 135000 | M18: 100000 | O18: 300000 | Q18: =SUM(K18,M18,O18) -> 535000 | R18: =SUM(L18,N18,P18) -> 0 | S18: =IF(R18=0,"",R18/Q18) | T18: =IF(R18="",T17,R18+T17) -> 3258092.6 | U18: =U17-R18 -> 5441907.3
B19: Total | C19: =SUM(C7:C18) -> 149636.88 | D19: =SUM(D7:D18) -> 561833.6 | E19: =SUM(E7:E18) -> 36688.65 | F19: =SUM(F7:F18) -> 157464.82 | G19: =SUM(G7:G18) -> 165873.49 | H19: =SUM(H7:H18) -> 86830.88 | I19: =SUM(I7:I18) -> 65269.07 | J19: =SUM(J7:J18) -> 54252.21 | ... R19: =SUM(R7:R18) -> 3258092.6 | S19: =IF(R19=0,"",R19/Q19) -> 0.37449341 | T19: Meta vs Real | U19: =R19-Q19 -> -5441907.3
B22: Falta para a Meta | K22: =IF(L19="","",100%-(L19/K19)) -> 0.58247503 | M22: =IF(N19="","",100%-(N19/M19)) -> 0.61393448 | O22: =IF(P19="","",100%-(P19/O19)) -> 0.6459907 | Q22: =IF(T18="","",100%-(T18/U4)) -> 0.62550659
B24: Atingimento da Meta | K24: =100%-K22 -> 0.41752497 | M24: =100%-M22 -> 0.38606552 | O24: =100%-O22 -> 0.3540093 | Q24: =100%-Q22 -> 0.37449341
K28: =B5 -> Data | L28: =Q6 -> Meta | M28: Verde | N28: Vermelho
K29: =B7 -> Janeiro | L29: =Q7 -> 550000 | M29: =IF(Q7<R7,R7,"") | N29: =IF(Q7>R7,R7,"") -> 399844.11
K30: =B8 -> Fevereiro | L30: =Q8 -> 600000 | M30: =IF(Q8<R8,R8,"") | N30: =IF(Q8>R8,R8,"") -> 401528.5
K31: =B9 -> Março | L31: =Q9 -> 685000 | M31: =IF(Q9<R9,R9,"") | N31: =IF(Q9>R9,R9,"") -> 666621.31
K32: =B10 -> Abril | L32: =Q10 -> 650000 | M32: =IF(Q10<R10,R10,"") | N32: =IF(Q10>R10,R10,"") -> 591216.71
K33: =B11 -> Maio | L33: =Q11 -> 800000 | M33: =IF(Q11<R11,R11,"") | N33: =IF(Q11>R11,R11,"") -> 395074.44
K34: =B12 -> Junho | L34: =Q12 -> 815000 | M34: =IF(Q12<R12,R12,"") | N34: =IF(Q12>R12,R12,"") -> 803807.58
K35: =B13 -> Julho | L35: =Q13 -> 900000 | M35: =IF(Q13<R13,R13,"") | N35: =IF(Q13>R13,R13,"") -> 0
K36: =B14 -> Agosto | L36: =Q14 -> 830000 | M36: =IF(Q14<R14,R14,"") | N36: =IF(Q14>R14,R14,"") -> 0
K37: =B15 -> Setembro | L37: =Q15 -> 910000 | M37: =IF(Q15<R15,R15,"") | N37: =IF(Q15>R15,R15,"") -> 0
K38: =B16 -> Outubro | L38: =Q16 -> 825000 | M38: =IF(Q16<R16,R16,"") | N38: =IF(Q16>R16,R16,"") -> 0
K39: =B17 -> Novembro | L39: =Q17 -> 600000 | M39: =IF(Q17<R17,R17,"") | N39: =IF(Q17>R17,R17,"") -> 0
K40: =B18 -> Dezembro | L40: =Q18 -> 535000 | M40: =IF(Q18<R18,R18,"") | N40: =IF(Q18>R18,R18,"") -> 0

Sheet Histórico de Fatu. FARDIN P.F.
C3: Histórico de Vendas e Faturamento FARDIN 2026
C5: FATURAMENTO GERAL
C6: Indicador | E6: Jan | F6: Fev | G6: Mar | H6: Abri | I6: Mai | J6: Jun | K6: Jul | L6: Ago | M6: Set | N6: Out | O6: Nov | P6: Dez | Q6: Total Anual
C7: Faturamento | E7: ='Meta x Real de Vendas FARDIN'!R7 -> 399844.11 | F7: ='Meta x Real de Vendas FARDIN'!R8 -> 401528.5 | G7: ='Meta x Real de Vendas FARDIN'!R9 -> 666621.31 | H7: ='Meta x Real de Vendas FARDIN'!R10 -> 591216.71 | I7: ='Meta x Real de Vendas FARDIN'!R11 -> 395074.44 | J7: ='Meta x Real de Vendas FARDIN'!R12 -> 803807.58 | K7: ='Meta x Real de Vendas Global'!E13 -> 0 | L7: ='Meta x Real de Vendas Global'!E14 -> 0 | M7: ='Meta x Real de Vendas Global'!E15 -> 0 | N7: ='Meta x Real de Vendas Global'!E16 -> 0 | O7: ='Meta x Real de Vendas Global'!E17 -> 0 | P7: ='Meta x Real de Vendas Global'!E18 -> 0 | Q7: =SUM(E7:P7) -> 3258092.6
C9: FATURAMENTO POR FAMÍLIA
C10: Representante | E10: Jan | F10: Fev | G10: Mar | H10: Abri | I10: Mai | J10: Jun | K10: Jul | L10: Ago | M10: Set | N10: Out | O10: Nov | P10: Dez | Q10: Total Anual
C11: Copinho | D11: Meta | E11: 37300 | F11: 37300 | G11: 37300 | H11: 69150 | I11: 85100 | J11: 75750 | K11: 74500 | Q11: =SUM(E11:P11) -> 416400 | T11: 700000
D12: Real | E12: 13415.91 | F12: =SUM(7488.52+8516.64+1250.88+328.12+73.15) -> 17657.31 | G12: 20333.44 | H12: 21588.52 | I12: 16089.72 | J12: 33848.22 | Q12: =SUM(E12:P12) -> 122933.12
D13: % de Atingimento | E13: =IF(E11="","",E12/E11) -> 0.35967587 | F13: =IF(F11="","",F12/F11) -> 0.47338633 | G13: =IF(G11="","",G12/G11) -> 0.54513244 | H13: =IF(H11="","",H12/H11) -> 0.31219841 | I13: =IF(I11="","",I12/I11) -> 0.18906839 | J13: =IF(J11="","",J12/J11) -> 0.44684119 | K13: =IF(K11="","",K12/K11) -> 0 | L13: =IF(L11="","",L12/L11) | ... Q13: =IF(Q11="","",Q12/Q11) -> 0.29522843
D14: % de Participação | E14: =IF(E12="","",E12/E7) -> 0.033552851 | F14: =IF(F12="","",F12/F7) -> 0.043975235 | G14: =IF(G12="","",G12/G7) -> 0.030502235 | H14: =IF(H12="","",H12/H7) -> 0.036515409 | I14: =IF(I12="","",I12/I7) -> 0.040725793 | J14: =IF(J12="","",J12/J7) -> 0.042109854 | K14: =IF(K12="","",K12/K7) | L14: =IF(L12="","",L12/L7) | ... P14: =IF(P12="","",P12/P7) | Q14: =SUM(E14:P14) -> 0.22738138
C15: Mariola Zero | D15: Meta | E15: 220800 | F15: 220800 | G15: 220800 | H15: 269750 | I15: 327100 | J15: 328150 | K15: 369500 | Q15: =SUM(E15:P15) -> 1956900
D16: Real | E16: 99559.96 | F16: =SUM(75713.31+59677.62+4405.25+7837.67+11785.36) -> 159419.21 | G16: 266441.51 | H16: 230083.54 | I16: 133304.93 | J16: 337002.5 | Q16: =SUM(E16:P16) -> 1225811.7
D17: % de Atingimento | E17: =IF(E15="","",E16/E15) -> 0.45090562 | F17: =IF(F15="","",F16/F15) -> 0.72200729 | G17: =IF(G15="","",G16/G15) -> 1.2067097 | H17: =IF(H15="","",H16/H15) -> 0.85295103 | I17: =IF(I15="","",I16/I15) -> 0.40753571 | J17: =IF(J15="","",J16/J15) -> 1.026977 | K17: =IF(K15="","",K16/K15) -> 0 | L17: =IF(L15="","",L16/L15) | ... Q17: =IF(Q15="","",Q16/Q15) -> 0.62640485
D18: % de Participação | E18: =IF(E16="","",E16/E7) -> 0.24899694 | F18: =IF(F16="","",F16/F7) -> 0.39703087 | G18: =IF(G16="","",G16/G7) -> 0.39968946 | H18: =IF(H16="","",H16/H7) -> 0.38916955 | I18: =IF(I16="","",I16/I7) -> 0.33741725 | J18: =IF(J16="","",J16/J7) -> 0.41925768 | K18: =IF(K16="","",K16/K7) | L18: =IF(L16="","",L16/L7) | ... P18: =IF(P16="","",P16/P7) | Q18: =SUM(E18:P18) -> 2.1915617
C19: Mariola | D19: Meta | E19: 245300 | F19: 245300 | G19: 245300 | H19: 202550 | I19: 253100 | J19: 265100 | K19: 288700 | Q19: =SUM(E19:P19) -> 1745350
D20: Real | E20: 176162.33 | F20: =SUM(4728.05+121796.92+2942.03+1907.94+2912.52) -> 134287.46 | G20: 206899.77 | H20: 201955.61 | I20: 130819.59 | J20: 228231.73 | Q20: =SUM(E20:P20) -> 1078356.5
D21: % de Atingimento | E21: =IF(E19="","",E20/E19) -> 0.71815055 | F21: =IF(F19="","",F20/F19) -> 0.54744174 | G21: =IF(G19="","",G20/G19) -> 0.84345605 | H21: =IF(H19="","",H20/H19) -> 0.99706547 | I21: =IF(I19="","",I20/I19) -> 0.51686918 | J21: =IF(J19="","",J20/J19) -> 0.86092693 | K21: =IF(K19="","",K20/K19) -> 0 | L21: =IF(L19="","",L20/L19) | ... Q21: =IF(Q19="","",Q20/Q19) -> 0.61784541
D22: % de Participação | E22: =IF(E20="","",E20/E7) -> 0.44057753 | F22: =IF(F20="","",F20/F7) -> 0.33444067 | G22: =IF(G20="","",G20/G7) -> 0.31037077 | H22: =IF(H20="","",H20/H7) -> 0.3415932 | I22: =IF(I20="","",I20/I7) -> 0.33112643 | J22: =IF(J20="","",J20/J7) -> 0.28393827 | K22: =IF(K20="","",K20/K7) | L22: =IF(L20="","",L20/L7) | ... P22: =IF(P20="","",P20/P7) | Q22: =SUM(E22:P22) -> 2.0420469
C23: Mariola Cristalizada | D23: Meta | E23: 90600 | F23: 90600 | G23: 90600 | H23: 76850 | I23: 96300 | J23: 107300 | K23: 126700 | Q23: =SUM(E23:P23) -> 678950
D24: Real | E24: 78718.97 | F24: =SUM(8669.23+36622.42+4222.38+3133.32+3150.01) -> 55797.36 | G24: 133952.03 | H24: 107925.95 | I24: 79848.98 | J24: 159606.32 | Q24: =SUM(E24:P24) -> 615849.61
D25: % de Atingimento | E25: =IF(E23="","",E24/E23) -> 0.8688628 | F25: =IF(F23="","",F24/F23) -> 0.6158649 | G25: =IF(G23="","",G24/G23) -> 1.4784992 | H25: =IF(H23="","",H24/H23) -> 1.4043715 | I25: =IF(I23="","",I24/I23) -> 0.82916906 | J25: =IF(J23="","",J24/J23) -> 1.4874774 | K25: =IF(K23="","",K24/K23) -> 0 | L25: =IF(L23="","",L24/L23) | ... Q25: =IF(Q23="","",Q24/Q23) -> 0.9070618
D26: % de Participação | E26: =IF(E24="","",E24/E7) -> 0.19687415 | F26: =IF(F24="","",F24/F7) -> 0.13896239 | G26: =IF(G24="","",G24/G7) -> 0.20094172 | H26: =IF(H24="","",H24/H7) -> 0.18254888 | I26: =IF(I24="","",I24/I7) -> 0.20211123 | J26: =IF(J24="","",J24/J7) -> 0.19856285 | K26: =IF(K24="","",K24/K7) | L26: =IF(L24="","",L24/L7) | ... P26: =IF(P24="","",P24/P7) | Q26: =SUM(E26:P26) -> 1.1200012
C27: Gominha | D27: Meta | E27: 10600 | F27: 10600 | G27: 10600 | H27: 23400 | I27: 27700 | J27: 28150 | K27: 27800 | Q27: =SUM(E27:P27) -> 138850
D28: Real | E28: 19115.74 | F28: =SUM(2044.13+11332.28+1128.44+672.2+386.49) -> 15563.54 | G28: 32056.41 | H28: 20017.02 | I28: 26905.74 | J28: 30936.71 | Q28: =SUM(E28:P28) -> 144595.16
D29: % de Atingimento | E29: =IF(E27="","",E28/E27) -> 1.8033717 | F29: =IF(F27="","",F28/F27) -> 1.4682585 | G29: =IF(G27="","",G28/G27) -> 3.0241896 | H29: =IF(H27="","",H28/H27) -> 0.85542821 | I29: =IF(I27="","",I28/I27) -> 0.97132635 | J29: =IF(J27="","",J28/J27) -> 1.098995 | K29: =IF(K27="","",K28/K27) -> 0 | L29: =IF(L27="","",L28/L27) | ... Q29: =IF(Q27="","",Q28/Q27) -> 1.0413767
D30: % de Participação | E30: =IF(E28="","",E28/E7) -> 0.047807982 | F30: =IF(F28="","",F28/F7) -> 0.038760736 | G30: =IF(G28="","",G28/G7) -> 0.048087887 | H30: =IF(H28="","",H28/H7) -> 0.033857331 | I30: =IF(I28="","",I28/I7) -> 0.068102963 | J30: =IF(J28="","",J28/J7) -> 0.038487706 | K30: =IF(K28="","",K28/K7) | L30: =IF(L28="","",L28/L7) | ... P30: =IF(P28="","",P28/P7) | Q30: =SUM(E30:P30) -> 0.2751046
C31: Goiabada | D31: Meta | E31: 3200 | F31: 3200 | G31: 3200 | H31: 8300 | I31: 10700 | J31: 10550 | K31: 12800 | Q31: =SUM(E31:P31) -> 51950
D32: Real | E32: 5250.24 | F32: =SUM(2101.52+514.8+391.56+1020.96+1029.44) -> 5058.28 | G32: 12754.32 | H32: 4251.18 | I32: 4887.48 | J32: 7325.91 | Q32: =SUM(E32:P32) -> 39527.41
D33: % de Atingimento | E33: =IF(E31="","",E32/E31) -> 1.6407 | F33: =IF(F31="","",F32/F31) -> 1.5807125 | G33: =IF(G31="","",G32/G31) -> 3.985725 | H33: =IF(H31="","",H32/H31) -> 0.51219036 | I33: =IF(I31="","",I32/I31) -> 0.45677383 | J33: =IF(J31="","",J32/J31) -> 0.69439905 | K33: =IF(K31="","",K32/K31) -> 0 | L33: =IF(L31="","",L32/L31) | ... Q33: =IF(Q31="","",Q32/Q31) -> 0.76087411
D34: % de Participação | E34: =IF(E32="","",E32/E7) -> 0.013130717 | F34: =IF(F32="","",F32/F7) -> 0.012597562 | G34: =IF(G32="","",G32/G7) -> 0.019132782 | H34: =IF(H32="","",H32/H7) -> 0.0071905613 | I34: =IF(I32="","",I32/I7) -> 0.012371036 | J34: =IF(J32="","",J32/J7) -> 0.0091140096 | K34: =IF(K32="","",K32/K7) | L34: =IF(L32="","",L32/L7) | ... P34: =IF(P32="","",P32/P7) | Q34: =SUM(E34:P34) -> 0.073536667

Sheet Histórico de Fatu. FARDIN P.R.
C3: Histórico de Vendas e Faturamento FARDIN 2026
C5: FATURAMENTO GERAL
C6: Indicador | E6: Jan | F6: Fev | G6: Mar | H6: Abri | I6: Mai | J6: Jun | K6: Jul | L6: Ago | M6: Set | N6: Out | O6: Nov | P6: Dez | Q6: Total Anual
C7: Faturamento | E7: ='Meta x Real de Vendas FARDIN'!R7 -> 399844.11 | F7: ='Meta x Real de Vendas FARDIN'!R8 -> 401528.5 | G7: ='Meta x Real de Vendas FARDIN'!R9 -> 666621.31 | H7: ='Meta x Real de Vendas FARDIN'!R10 -> 591216.71 | I7: ='Meta x Real de Vendas FARDIN'!R11 -> 395074.44 | J7: ='Meta x Real de Vendas FARDIN'!R12 -> 803807.58 | K7: ='Meta x Real de Vendas Global'!E13 -> 0 | L7: ='Meta x Real de Vendas Global'!E14 -> 0 | M7: ='Meta x Real de Vendas Global'!E15 -> 0 | N7: ='Meta x Real de Vendas Global'!E16 -> 0 | O7: ='Meta x Real de Vendas Global'!E17 -> 0 | P7: ='Meta x Real de Vendas Global'!E18 -> 0 | Q7: =SUM(E7:P7) -> 3258092.6
C8: Nº De Vendas | E8: 195 | F8: 166 | G8: 227 | H8: 205 | I8: 194 | J8: =SUM(J21+J30+J39+J45+J51+J57+J66+J72+J78+J87) -> 262 | Q8: =SUM(E8:P8) -> 1249
C9: Ticket Médio | E9: =IF(E7=0,"",E7/E8) -> 2050.4826 | F9: =IF(F7=0,"",F7/F8) -> 2418.8464 | G9: =IF(G7=0,"",G7/G8) -> 2936.6578 | H9: =IF(H7=0,"",H7/H8) -> 2883.984 | I9: =IF(I7=0,"",I7/I8) -> 2036.4662 | J9: =IF(J7=0,"",J7/J8) -> 3067.9679 | K9: =IF(K7=0,"",K7/K8) | L9: =IF(L7=0,"",L7/L8) | ... Q9: =IF(Q7=0,"",Q7/Q8) -> 2608.561
C10: Nº Clientes Carteira | E10: 376 | F10: 391 | G10: 529 | H10: 537 | I10: =106+265+8+113+54+3 -> 549 | J10: =SUM(J20+J29+J38+J44+J50+J56+J65+J71+J77+J86) -> 572 | Q10: =AVERAGE(E10:P10) -> 492.33333
C11: Nº Clientes Compra | E11: 158 | F11: 142 | G11: 196 | H11: 175 | I11: =24+108+3+24+8+2 -> 169 | J11: =26+122+11+47+13+3+1 -> 223 | Q11: =AVERAGE(E11:P11) -> 177.16667
C12: Taxa de Recompra | E12: =IF(E10="","",E11/E10) -> 0.42021277 | F12: =IF(F10="","",F11/F10) -> 0.36317136 | G12: =IF(G10="","",G11/G10) -> 0.3705104 | H12: =IF(H10="","",H11/H10) -> 0.32588454 | I12: =IF(I10="","",I11/I10) -> 0.30783242 | J12: =IF(J10="","",J11/J10) -> 0.38986014 | K12: =IF(K10="","",K11/K10) | L12: =IF(L10="","",L11/L10) | ... Q12: =IF(Q10="","",Q11/Q10) -> 0.35985105
C14: FATURAMENTO POR REPRESENTANTE
C15: Representante | E15: Jan | F15: Fev | G15: Mar | H15: Abri | I15: Mai | J15: Jun | K15: Jul | L15: Ago | M15: Set | N15: Out | O15: Nov | P15: Dez | Q15: Total Anual
C16: Fardin | D16: Meta Venda (PV) | E16: 115000 | F16: 120000 | G16: 120000 | H16: 175000 | I16: 185000 | J16: 180000 | K16: 170000 | Q16: =SUM(E16:P16) -> 1065000
D17: Venda (PV) | E17: 71066.97 | F17: 137152.82 | G17: 198397.41 | H17: 169011.6 | I17: 80664.86 | J17: 173814.86 | Q17: =SUM(E17:P17) -> 830108.52
D18: Atingimento | E18: =IF(E16=0,"",E17/E16) -> 0.61797365 | F18: =IF(F16=0,"",F17/F16) -> 1.1429402 | G18: =IF(G16=0,"",G17/G16) -> 1.6533118 | H18: =IF(H16=0,"",H17/H16) -> 0.96578057 | I18: =IF(I16=0,"",I17/I16) -> 0.43602627 | J18: =IF(J16=0,"",J17/J16) -> 0.96563811 | K18: =IF(K16=0,"",K17/K16) -> 0 | L18: =IF(L16=0,"",L17/L16) | ... Q18: =IF(Q16=0,"",Q17/Q16) -> 0.77944462
D19: Faturamento (NF) | E19: 51609.93 | F19: 108390.94 | G19: 167634.25 | H19: 113846.33 | I19: 100565.47 | J19: 139358.72 | Q19: =SUM(E19:P19) -> 681405.64
D20: Nº Clientes Carteira | E20: 75 | F20: 75 | G20: 75 | H20: 75 | I20: 106 | J20: 111 | Q20: =IF(SUM(E20:P20)=0,"",AVERAGE(E20:P20)) -> 86.166667
D21: Nº De Vendas | E21: 12 | F21: 30 | G21: 33 | H21: 25 | I21: 27 | J21: 26 | Q21: =IF(SUM(E21:P21)=0,"",AVERAGE(E21:P21)) -> 25.5
C22: Wilson | D22: Meta Venda (PV) | E22: 360000 | F22: 320000 | G22: 400000 | H22: 360000 | I22: 450000 | J22: 475000 | K22: 510000 | Q22: =SUM(E22:P22) -> 2875000
D23: Venda (PV) | E23: 295776.23 | F23: 236813.43 | G23: 302009.59 | H23: 342226.31 | I23: 230350.54 | J23: 354218.8 | Q23: =SUM(E23:P23) -> 1761394.9
D24: Atingimento | E24: =IF(E22=0,"",E23/E22) -> 0.82160064 | F24: =IF(F22=0,"",F23/F22) -> 0.74004197 | G24: =IF(G22=0,"",G23/G22) -> 0.75502398 | H24: =IF(H22=0,"",H23/H22) -> 0.95062864 | I24: =IF(I22=0,"",I23/I22) -> 0.51189009 | J24: =IF(J22=0,"",J23/J22) -> 0.74572379 | K24: =IF(K22=0,"",K23/K22) -> 0 | L24: =IF(L22=0,"",L23/L22) | ... Q24: =IF(Q22=0,"",Q23/Q22) -> 0.6126591
D25: Meta Clientes Novos | E25: 0 | F25: 0 | G25: 0 | H25: 0 | I25: 2 | J25: 0 | Q25: =SUM(E25:P25) -> 2
D26: Efetivado Clientes Novos | E26: 0 | F26: 0 | G26: 0 | H26: 0 | I26: 0 | J26: 0 | Q26: =SUM(E26:P26) -> 0
D27: Atingimento | E27: =IF(E25=0,"",E26/E25) | F27: =IF(F25=0,"",F26/F25) | G27: =IF(G25=0,"",G26/G25) | H27: =IF(H25=0,"",H26/H25) | I27: =IF(I25=0,"",I26/I25) -> 0 | J27: =IF(J25=0,"",J26/J25) | K27: =IF(K25=0,"",K26/K25) | L27: =IF(L25=0,"",L26/L25) | ... P27: =IF(P25=0,"",P26/P25) | Q27: =IF(Q23=0,"",Q23/Q22) -> 0.6126591
D28: Faturamento (NF) | E28: 306034.16 | F28: 243983.88 | G28: 302009.59 | H28: 335993.99 | I28: 233324 | J28: 355781.07 | Q28: =SUM(E28:P28) -> 1777126.7
D29: Nº Clientes Carteira | E29: 264 | F29: 264 | G29: 264 | H29: 264 | I29: 265 | J29: 274 | Q29: =IF(SUM(E29:P29)=0,"",AVERAGE(E29:P29)) -> 265.83333
D30: Nº De Vendas | E30: 142 | F30: 126 | G30: 133 | H30: 142 | I30: 130 | J30: 160 | Q30: =IF(SUM(E30:P30)=0,"",AVERAGE(E30:P30)) -> 138.83333
C31: Ana | D31: Meta Venda (PV) | E31: 15000 | F31: 15000 | G31: 15000 | H31: 15000 | I31: 20000 | J31: 25000 | K31: 25000 | Q31: =SUM(E31:P31) -> 130000
D32: Venda (PV) | E32: 0 | F32: 9487.08 | G32: 8433.31 | H32: 13456.8 | I32: 10315.51 | J32: 32841.5 | Q32: =SUM(E32:P32) -> 74534.2
D33: Atingimento | E33: =IF(E31=0,"",E32/E31) -> 0 | F33: =IF(F31=0,"",F32/F31) -> 0.632472 | G33: =IF(G31=0,"",G32/G31) -> 0.56222067 | H33: =IF(H31=0,"",H32/H31) -> 0.89712 | I33: =IF(I31=0,"",I32/I31) -> 0.5157755 | J33: =IF(J31=0,"",J32/J31) -> 1.31366 | K33: =IF(K31=0,"",K32/K31) -> 0 | L33: =IF(L31=0,"",L32/L31) | ... Q33: =IF(Q31=0,"",Q32/Q31) -> 0.57334
D34: Meta Clientes Novos | E34: 0 | F34: 0 | G34: 0 | H34: 0 | I34: 1 | J34: 3 | K34: 3 | Q34: =SUM(E34:P34) -> 7
D35: Efetivado Clientes Novos | E35: 0 | F35: 0 | G35: 0 | H35: 0 | I35: 2 | J35: 7 | Q35: =SUM(E35:P35) -> 9
D36: Atingimento | E36: =IF(E34=0,"",E35/E34) | F36: =IF(F34=0,"",F35/F34) | G36: =IF(G34=0,"",G35/G34) | H36: =IF(H34=0,"",H35/H34) | I36: =IF(I34=0,"",I35/I34) -> 2 | J36: =IF(J34=0,"",J35/J34) -> 2.3333333 | K36: =IF(K34=0,"",K35/K34) -> 0 | L36: =IF(L34=0,"",L35/L34) | ... Q36: =IF(Q34=0,"",Q35/Q34) -> 1.2857143
D37: Faturamento (NF) | E37: 0 | F37: 0 | G37: 18280.39 | H37: 13456.8 | I37: 10431.63 | J37: 32841.5 | Q37: =SUM(E37:P37) -> 75010.32
D38: Nº Clientes Carteira | E38: 7 | F38: 7 | G38: 7 | H38: 6 | I38: 8 | J38: 15 | Q38: =IF(SUM(E38:P38)=0,"",AVERAGE(E38:P38)) -> 8.3333333
D39: Nº De Vendas | E39: 3 | F39: 3 | G39: 1 | H39: 2 | I39: 3 | J39: 11 | Q39: =IF(SUM(E39:P39)=0,"",AVERAGE(E39:P39)) -> 3.8333333
C40: Capelini | D40: Meta Venda (PV) | E40: 25000 | F40: 25000 | G40: 25000 | H40: 30000 | I40: 35000 | J40: 40000 | K40: 45000 | Q40: =SUM(E40:P40) -> 225000
D41: Venda (PV) | E41: =14108.69+575.96 -> 14684.65 | F41: 15900.4 | G41: 35959.63 | H41: 34296.25 | I41: 31598.43 | J41: 66899.94 | Q41: =SUM(E41:P41) -> 199339.3
D42: Atingimento | E42: =IF(E40=0,"",E41/E40) -> 0.587386 | F42: =IF(F40=0,"",F41/F40) -> 0.636016 | G42: =IF(G40=0,"",G41/G40) -> 1.4383852 | H42: =IF(H40=0,"",H41/H40) -> 1.1432083 | I42: =IF(I40=0,"",I41/I40) -> 0.90281229 | J42: =IF(J40=0,"",J41/J40) -> 1.6724985 | K42: =IF(K40=0,"",K41/K40) -> 0 | L42: =IF(L40=0,"",L41/L40) | ... Q42: =IF(Q40=0,"",Q41/Q40) -> 0.88595244
D43: Faturamento (NF) | E43: =19292.33+575.96 -> 19868.29 | F43: 14916.5 | G43: 36084.77 | H43: 42732.44 | I43: 30006.44 | J43: 58414.03 | Q43: =SUM(E43:P43) -> 202022.47
D44: Nº Clientes Carteira | E44: 113 | F44: 113 | G44: 113 | H44: 113 | I44: 113 | J44: 113 | Q44: =IF(SUM(E44:P44)=0,"",AVERAGE(E44:P44)) -> 113
...

Sheet Orçamento Comercial
B2: Orçamento Comercial
B3: Meses | C3: Viagens | F3: Ponto de Venda | I3: Eventos
C4: 42100 | F4: 20000 | I4: 40000
C5: Planejado | D5: Realizado | E5: % | F5: Planejado | G5: Realizado | H5: % | I5: Planejado | J5: Realizado | K5: %
B6: 46023 | C6: =C4/12 -> 3508.3333 | E6: =IF(D6="","",D6/C6) | F6: =$F$4/12 -> 1666.6667 | H6: =IF(G6="","",G6/F6) | I6: =$I$4/12 -> 3333.3333 | J6: 600 | K6: =IF(J6="","",J6/I6) -> 0.18
B7: 46055 | C7: =$C$4/12 -> 3508.3333 | E7: =IF(D7="","",D7/C7) | F7: =$F$4/12 -> 1666.6667 | H7: =IF(G7="","",G7/F7) | I7: =$I$4/12 -> 3333.3333 | J7: 4197 | K7: =IF(J7="","",J7/I7) -> 1.2591
B8: 46086 | C8: =$C$4/12 -> 3508.3333 | D8: 10000 | E8: =IF(D8="","",D8/C8) -> 2.8503563 | F8: =$F$4/12 -> 1666.6667 | H8: =IF(G8="","",G8/F8) | I8: =$I$4/12 -> 3333.3333 | J8: 4526 | K8: =IF(J8="","",J8/I8) -> 1.3578
B9: 46117 | C9: =$C$4/12 -> 3508.3333 | E9: =IF(D9="","",D9/C9) | F9: =$F$4/12 -> 1666.6667 | H9: =IF(G9="","",G9/F9) | I9: =$I$4/12 -> 3333.3333 | K9: =IF(J9="","",J9/I9)
B10: 46148 | C10: =$C$4/12 -> 3508.3333 | E10: =IF(D10="","",D10/C10) | F10: =$F$4/12 -> 1666.6667 | H10: =IF(G10="","",G10/F10) | I10: =$I$4/12 -> 3333.3333 | K10: =IF(J10="","",J10/I10)
B11: 46179 | C11: =$C$4/12 -> 3508.3333 | E11: =IF(D11="","",D11/C11) | F11: =$F$4/12 -> 1666.6667 | H11: =IF(G11="","",G11/F11) | I11: =$I$4/12 -> 3333.3333 | K11: =IF(J11="","",J11/I11)
B12: 46210 | C12: =$C$4/12 -> 3508.3333 | E12: =IF(D12="","",D12/C12) | F12: =$F$4/12 -> 1666.6667 | H12: =IF(G12="","",G12/F12) | I12: =$I$4/12 -> 3333.3333 | K12: =IF(J12="","",J12/I12)
B13: 46241 | C13: =$C$4/12 -> 3508.3333 | E13: =IF(D13="","",D13/C13) | F13: =$F$4/12 -> 1666.6667 | H13: =IF(G13="","",G13/F13) | I13: =$I$4/12 -> 3333.3333 | K13: =IF(J13="","",J13/I13)
B14: 46272 | C14: =$C$4/12 -> 3508.3333 | E14: =IF(D14="","",D14/C14) | F14: =$F$4/12 -> 1666.6667 | H14: =IF(G14="","",G14/F14) | I14: =$I$4/12 -> 3333.3333 | K14: =IF(J14="","",J14/I14)
B15: 46303 | C15: =$C$4/12 -> 3508.3333 | E15: =IF(D15="","",D15/C15) | F15: =$F$4/12 -> 1666.6667 | H15: =IF(G15="","",G15/F15) | I15: =$I$4/12 -> 3333.3333 | K15: =IF(J15="","",J15/I15)
B16: 46334 | C16: =$C$4/12 -> 3508.3333 | E16: =IF(D16="","",D16/C16) | F16: =$F$4/12 -> 1666.6667 | H16: =IF(G16="","",G16/F16) | I16: =$I$4/12 -> 3333.3333 | K16: =IF(J16="","",J16/I16)
B17: 46364 | C17: =$C$4/12 -> 3508.3333 | E17: =IF(D17="","",D17/C17) | F17: =$F$4/12 -> 1666.6667 | H17: =IF(G17="","",G17/F17) | I17: =$I$4/12 -> 3333.3333 | K17: =IF(J17="","",J17/I17)
B18: TOTAL | C18: =SUM(C6:C17) -> 42100 | D18: =SUM(D6:D17) -> 10000 | E18: =IF(D18=0,"",D18/C18) -> 0.23752969 | F18: =SUM(F6:F17) -> 20000 | G18: =SUM(G6:G17) -> 0 | H18: =IF(G18=0,"",G18/F18) | I18: =SUM(I6:I17) -> 40000 | J18: =SUM(J6:J17) -> 9323 | K18: =IF(J18=0,"",J18/I18) -> 0.233075

Sheet  Agenda de Impacto
C2: CALENDÁRIO DE EVENTOS COMERCIAIS
C3: 2026
C4: JANEIRO | K4: FEVEREIRO | S4: MARÇO | AA4: ABRIL
C5: do | D5: se | E5: te | F5: qu | G5: qu | H5: se | I5: sá | K5: do | L5: se | M5: te | N5: qu | O5: qu | P5: se | Q5: sá | S5: do | T5: se | U5: te | V5: qu | W5: qu | X5: se | Y5: sá | AA5: do | AB5: se | AC5: te | AD5: qu | AE5: qu | AF5: se | AG5: sá
G6: 1 | H6: 2 | I6: 3 | K6: 1 | L6: 2 | M6: 3 | N6: 4 | O6: 5 | P6: 6 | Q6: 7 | S6: 1 | T6: 2 | U6: 3 | V6: 4 | W6: 5 | X6: 6 | Y6: 7 | AD6: 1 | AE6: 2 | AF6: 3 | AG6: 4
C7: 4 | D7: 5 | E7: 6 | F7: 7 | G7: 8 | H7: 9 | I7: 10 | K7: 8 | L7: 9 | M7: 10 | N7: 11 | O7: 12 | P7: 13 | Q7: 14 | S7: 8 | T7: 9 | U7: 10 | V7: 11 | W7: 12 | X7: 13 | Y7: 14 | AA7: 5 | AB7: 6 | AC7: 7 | AD7: 8 | AE7: 9 | AF7: 10 | AG7: 11
C8: 11 | D8: 12 | E8: 13 | F8: 14 | G8: 15 | H8: 16 | I8: 17 | K8: 15 | L8: 16 | M8: 17 | N8: 18 | O8: 19 | P8: 20 | Q8: 21 | S8: 15 | T8: 16 | U8: 17 | V8: 18 | W8: 19 | X8: 20 | Y8: 21 | AA8: 12 | AB8: 13 | AC8: 14 | AD8: 15 | AE8: 16 | AF8: 17 | AG8: 18
C9: 18 | D9: 19 | E9: 20 | F9: 21 | G9: 22 | H9: 23 | I9: 24 | K9: 22 | L9: 23 | M9: 24 | N9: 25 | O9: 26 | P9: 27 | Q9: 28 | S9: 22 | T9: 23 | U9: 24 | V9: 25 | W9: 26 | X9: 27 | Y9: 28 | AA9: 19 | AB9: 20 | AC9: 21 | AD9: 22 | AE9: 23 | AF9: 24 | AG9: 25
C10: 25 | D10: 26 | E10: 27 | F10: 28 | G10: 29 | H10: 30 | S10: 29 | T10: 30 | U10: 31 | AA10: 26 | AB10: 27 | AC10: 28 | AD10: 29 | AE10: 30
C12: MAIO | K12: JUNHO | S12: JULHO | AA12: AGOSTO
C13: do | D13: se | E13: te | F13: qu | G13: qu | H13: se | I13: sá | K13: do | L13: se | M13: te | N13: qu | O13: qu | P13: se | Q13: sá | S13: do | T13: se | U13: te | V13: qu | W13: qu | X13: se | Y13: sá | AA13: do | AB13: se | AC13: te | AD13: qu | AE13: qu | AF13: se | AG13: sá
H14: 1 | I14: 2 | L14: 1 | M14: 2 | N14: 3 | O14: 4 | P14: 5 | Q14: 6 | V14: 1 | W14: 2 | X14: 3 | Y14: 4 | AG14: 1
C15: 3 | D15: 4 | E15: 5 | F15: 6 | G15: 7 | H15: 8 | I15: 9 | K15: 7 | L15: 8 | M15: 9 | N15: 10 | O15: 11 | P15: 12 | Q15: 13 | S15: 5 | T15: 6 | U15: 7 | V15: 8 | W15: 9 | X15: 10 | Y15: 11 | AA15: 2 | AB15: 3 | AC15: 4 | AD15: 5 | AE15: 6 | AF15: 7 | AG15: 8
C16: 10 | D16: 11 | E16: 12 | F16: 13 | G16: 14 | H16: 15 | I16: 16 | K16: 14 | L16: 15 | M16: 16 | N16: 17 | O16: 18 | P16: 19 | Q16: 20 | S16: 12 | T16: 13 | U16: 14 | V16: 15 | W16: 16 | X16: 17 | Y16: 18 | AA16: 9 | AB16: 10 | AC16: 11 | AD16: 12 | AE16: 13 | AF16: 14 | AG16: 15
C17: 17 | D17: 18 | E17: 19 | F17: 20 | G17: 21 | H17: 22 | I17: 23 | K17: 21 | L17: 22 | M17: 23 | N17: 24 | O17: 25 | P17: 26 | Q17: 27 | S17: 19 | T17: 20 | U17: 21 | V17: 22 | W17: 23 | X17: 24 | Y17: 25 | AA17: 16 | AB17: 17 | AC17: 18 | AD17: 19 | AE17: 20 | AF17: 21 | AG17: 22
C18: 24 | D18: 25 | E18: 26 | F18: 27 | G18: 28 | H18: 29 | I18: 30 | K18: 28 | L18: 29 | M18: 30 | S18: 26 | T18: 27 | U18: 28 | V18: 29 | W18: 30 | X18: 31 | AA18: 23 | AB18: 24 | AC18: 25 | AD18: 26 | AE18: 27 | AF18: 28 | AG18: 29
C19: 31 | AA19: 30 | AB19: 31
C20: SETEMBRO | K20: OUTUBRO | S20: NOVEMBRO | AA20: DEZEMBRO
C21: do | D21: se | E21: te | F21: qu | G21: qu | H21: se | I21: sá | K21: do | L21: se | M21: te | N21: qu | O21: qu | P21: se | Q21: sá | S21: do | T21: se | U21: te | V21: qu | W21: qu | X21: se | Y21: sá | AA21: do | AB21: se | AC21: te | AD21: qu | AE21: qu | AF21: se | AG21: sá
E22: 1 | F22: 2 | G22: 3 | H22: 4 | I22: 5 | O22: 1 | P22: 2 | Q22: 3 | S22: 1 | T22: 2 | U22: 3 | V22: 4 | W22: 5 | X22: 6 | Y22: 7 | AC22: 1 | AD22: 2 | AE22: 3 | AF22: 4 | AG22: 5
C23: 6 | D23: 7 | E23: 8 | F23: 9 | G23: 10 | H23: 11 | I23: 12 | K23: 4 | L23: 5 | M23: 6 | N23: 7 | O23: 8 | P23: 9 | Q23: 10 | S23: 8 | T23: 9 | U23: 10 | V23: 11 | W23: 12 | X23: 13 | Y23: 14 | AA23: 6 | AB23: 7 | AC23: 8 | AD23: 9 | AE23: 10 | AF23: 11 | AG23: 12
C24: 13 | D24: 14 | E24: 15 | F24: 16 | G24: 17 | H24: 18 | I24: 19 | K24: 11 | L24: 12 | M24: 13 | N24: 14 | O24: 15 | P24: 16 | Q24: 17 | S24: 15 | T24: 16 | U24: 17 | V24: 18 | W24: 19 | X24: 20 | Y24: 21 | AA24: 13 | AB24: 14 | AC24: 15 | AD24: 16 | AE24: 17 | AF24: 18 | AG24: 19
C25: 20 | D25: 21 | E25: 22 | F25: 23 | G25: 24 | H25: 25 | I25: 26 | K25: 18 | L25: 19 | M25: 20 | N25: 21 | O25: 22 | P25: 23 | Q25: 24 | S25: 22 | T25: 23 | U25: 24 | V25: 25 | W25: 26 | X25: 27 | Y25: 28 | AA25: 20 | AB25: 21 | AC25: 22 | AD25: 23 | AE25: 24 | AF25: 25 | AG25: 26
C26: 27 | D26: 28 | E26: 29 | F26: 30 | K26: 25 | L26: 26 | M26: 27 | N26: 28 | O26: 29 | P26: 30 | Q26: 31 | S26: 29 | T26: 30 | AA26: 27 | AB26: 28 | AC26: 29 | AD26: 30 | AE26: 31
D28: Dias das Crianças | I28: Inverno (Início/ Fim) | S28: *Pontos Importantes para Olhar
D29: Cosme e Damião | I29: Feiras Anuais | T29: Feriado
D30: Festa Junina | I30: Feriados Nacionais | T30: Eleição
D31: Volta as aulas | T31: Férias Gerais
D32: Halloween

Sheet Gráficos
B2: Painel de Gestão Comercial 2025

Sheet Faturamento per Capita
B2: Avaliação de Desempenho Faturamento per Capita | E2: Período Base | F2: Meses | G2: R$ Vendas | H2: Qtd de Funcionários | I2: R$ per capita | L2: Gráfico
F3: 44927 | G3: 1129945.3 | H3: 107 | I3: =IF(H3="","",G3/H3) -> 10560.236 | L3: =F18 -> -256856.65
F4: 44958 | G4: 1286464.9 | H4: 115 | I4: =IF(H4="","",G4/H4) -> 11186.651 | L4: =F19 -> -74151.25
F5: 44986 | G5: 1452465.7 | H5: 113 | I5: =IF(H5="","",G5/H5) -> 12853.679 | L5: =F20 -> -94247.815
F6: 45017 | G6: 1269878 | H6: 102 | I6: =IF(H6="","",G6/H6) -> 12449.784 | L6: =F21 -> 69162.474
F7: 45047 | G7: 1516636.7 | H7: 112 | I7: =IF(H7="","",G7/H7) -> 13541.399 | L7: =F22
F8: 45078 | G8: 1464550.4 | H8: 112.38 | I8: =IF(H8="","",G8/H8) -> 13032.126 | L8: =F23
F9: 45108 | G9: 1507031.7 | H9: 112.619 | I9: =IF(H9="","",G9/H9) -> 13381.682 | L9: =F24
F10: 45139 | G10: 1391727.9 | H10: 117.174 | I10: =IF(H10="","",G10/H10) -> 11877.446 | L10: =F25
F11: 45170 | G11: 1228016.1 | H11: 119 | I11: =IF(H11="","",G11/H11) -> 10319.463 | L11: =F26
F12: 45200 | G12: 1536054.9 | H12: 120 | I12: =IF(H12="","",G12/H12) -> 12800.457 | L12: =F27
F13: 45231 | G13: 1418259.7 | H13: 119 | I13: =IF(H13="","",G13/H13) -> 11918.149 | L13: =F28
F14: 45261 | G14: 918650.63 | H14: 104.85 | I14: =IF(H14="","",G14/H14) -> 8761.5701 | L14: =F29
F15: Média | G15: =IF(SUM(G3:G14)=0,"",AVERAGE(G3:G14)) -> 1343306.8 | H15: =IF(SUM(H3:H14)=0,"",AVERAGE(H3:H14)) -> 112.83525 | I15: =IF(H15="","",G15/H15) -> 11905.028
B16: Meses | C16: R$ Vendas | D16: Qtd de Funcionários | E16: R$ per Capita | F16: Ganho (R$) | L16: =AVERAGE(C18:C21) -> 1365533
F17: Mês | G17: Acumulado | H17: Média Mensal | I17: Anualizado | L17: =(L16-G15)/G15 -> 0.016545885
B18: 45292 | C18: 1112221.6 | D18: 115 | E18: =IF(C18="","",C18/D18) -> 9671.492 | F18: =IF(E18="","",((E18-$I$15))*D18) -> -256856.65 | G18: =IF(F18="","",F18) -> -256856.65 | H18: =IF(F18="","",AVERAGE(F18:F18)) -> -256856.65 | I18: =IF(H18="","",(H18*12)) -> -3082279.8
B19: 45324 | C19: 1396119.7 | D19: 123.5 | E19: =IF(C19="","",C19/D19) -> 11304.613 | F19: =IF(E19="","",((E19-$I$15))*D19) -> -74151.25 | G19: =IF(F19="","",F19) -> -74151.25 | H19: =IF(F19="","",AVERAGE(F19:F19)) -> -74151.25 | I19: =IF(H19="","",(H19*12)) -> -889815
B20: 45356 | C20: 1365308.6 | D20: 122.6 | E20: =IF(C20="","",C20/D20) -> 11136.286 | F20: =IF(E20="","",((E20-$I$15))*D20) -> -94247.815 | G20: =IF(F20="","",F20+G19) -> -168399.06 | H20: =IF(F20="","",AVERAGE(F18:F20)) -> -141751.91 | I20: =IF(H20="","",(H20*12)) -> -1701022.9
B21: 45388 | C21: 1588482.2 | D21: 127.62 | E21: =IF(C21="","",C21/D21) -> 12446.969 | F21: =IF(E21="","",((E21-$I$15))*D21) -> 69162.474 | G21: =IF(F21="","",F21+G20) -> -99236.591 | H21: =IF(F21="","",AVERAGE(F18:F21)) -> -89023.31 | I21: =IF(H21="","",(H21*12)) -> -1068279.7
B22: 45420 | E22: =IF(C22="","",C22/D22) | F22: =IF(E22="","",((E22-$I$15))*D22) | G22: =IF(F22="","",F22+G21) | H22: =IF(F22="","",AVERAGE(F18:F22)) | I22: =IF(H22="","",(H22*12))
B23: 45452 | E23: =IF(C23="","",C23/D23) | F23: =IF(E23="","",((E23-$I$15))*D23) | G23: =IF(F23="","",F23+G22) | H23: =IF(F23="","",AVERAGE(F18:F23)) | I23: =IF(H23="","",(H23*12))
B24: 45484 | E24: =IF(C24="","",C24/D24) | F24: =IF(E24="","",((E24-$I$15))*D24) | G24: =IF(F24="","",F24+G23) | H24: =IF(F24="","",AVERAGE(F18:F24)) | I24: =IF(H24="","",(H24*12))
B25: 45516 | E25: =IF(C25="","",C25/D25) | F25: =IF(E25="","",((E25-$I$15))*D25) | G25: =IF(F25="","",F25+G24) | H25: =IF(F25="","",AVERAGE(F18:F25)) | I25: =IF(H25="","",(H25*12))
B26: 45548 | E26: =IF(C26="","",C26/D26) | F26: =IF(E26="","",((E26-$I$15))*D26) | G26: =IF(F26="","",F26+G25) | H26: =IF(F26="","",AVERAGE(F18:F26)) | I26: =IF(H26="","",(H26*12))
B27: 45580 | E27: =IF(C27="","",C27/D27) | F27: =IF(E27="","",((E27-$I$15))*D27) | G27: =IF(F27="","",F27+G26) | H27: =IF(F27="","",AVERAGE(F18:F27)) | I27: =IF(H27="","",(H27*12))
B28: 45612 | E28: =IF(C28="","",C28/D28) | F28: =IF(E28="","",((E28-$I$15))*D28) | G28: =IF(F28="","",F28+G27) | H28: =IF(F28="","",AVERAGE(F18:F28)) | I28: =IF(H28="","",(H28*12))
B29: 45644 | E29: =IF(C29="","",C29/D29) | F29: =IF(E29="","",((E29-$I$15))*D29) | G29: =IF(F29="","",F29+G28) | H29: =IF(F29="","",AVERAGE(F18:F29)) | I29: =IF(H29="","",(H29*12))
